Workbook

Sheet Notes
A1: 2022-002
A2: Program: | B2: IYS
A3: Analysis: | B3: Erinn Raftery
A4: Data Compiled: | B4: Erinn Raftery
A6: A detailed description of chlorophyll sampling is found on the Water Properties Website:
A7: http://www.waterproperties.ca/standards/Chlorophyll_sampling_12Feb2010.pdf
A9: Notes:
A10: Samples were analyzed on Turner Trilogy 7200-000, not the Turner 10-AU.
A11: On date of analysis July 6 2022, there were some issues with potential contamination of the acid with chlorophyll.
A12: Questionable and bad measurements from July 6 have been compared against their duplicate and the CTD fluorometer for agreement, and rejected with accompanying note.
A13: On date of analysis July 6-8 2022, the solid standard was lower than expected, however it was consistent. At this time, no correction has been applied.
A14: The measurements appear to be acceptable on these dates (unless otherwise flagged).
A15: No notes were recorded in chlorophyll filtation log 1 for this cruise.
A16: Samples 9A, 9B, and 14A were lost during filtering.
A17: Sample 657A/B do not have an associated CTD fluoro in the bottle csv.
A18: All samples were collected in duplicate (A/B). Where a duplicate was lost in analysis or matched poorly with both replicate and CTD fluorometer, the replicate is rejected, and Quality Flag 2 is used with an associated comment.
... A24: Updates
A25: 44769 | B25: ER | C25: Master List: changed Event 111 to Event 113 (Event 111 was a net cast); CHL: added appropriate "CHL" for all comments concerning CHL, and flags/comments entered for lost samples 9A/B and 14A.
A26: 44770 | B26: ER | C26: Updated with -99 pad values where samples lost during analysis. Changed handling of <MLD data - as is values reported when <MLD (not set to 0).
A28: Precision Statement:
A29: =CHL!B10 -> Chlorophyll values ranged from 0.00 - 0.81 ug/L in 414 samples. 71 of 414 samples were below Minimum Limit of Detection (<MLD). Samples <MLD that were collected in duplicate were not included in the %CV calculation. The original %CV for this dataset was 8.82% for 171 duplicate samples, excluding the average of duplicate pairs that were <MDL. 36 duplicates had a CV%>10, and 9 duplicates had a CV%>30. 10 duplicates were rejected (A or B), improving the %CV to 6.59% over 161 duplicate pairs, with 26 samples having a CV%>10 and 4 having a %CV>30. Our average dataset %CV is 3.89 % for 2013 - 2021 using the Turner 10-AU - so the overall quality of this dataset is acceptable.
A33: Minimum Limit of Detection (MLD): The stated MLD for the Turner Trilogy 7200-000 fluorometer is 0.025 ug/L for CHL-a. Samples below the MLD are reported as is and assigned Quality Flag 2 with an associated comment. Where samples are taken in duplicate and the average of the two is <MLD, the average value is reported as is and assigned Quality Flag 2 with an associated comment. Samples <MLD are excluded from precision (CV%) calculations.

Sheet CHL
A1: =Notes!A1 -> 2022-002
A3: Notes: | B3: Flags and comments apply to chlorophyll values only. No flags or comments are assigned for Phaeo-Pigment values
A4: HEADER: | B4: Chlorophyll samples were filtered onto 25mm GF/F filters and stored in glass scintillation vials at -80C prior to analysis | C4: Chlorophyll samples were filtered onto 25mm GF/F filters and stored in glass scintillation vials at -80C prior to analysis | D4: Chlorophyll samples were filtered onto 25mm GF/F filters and stored in glass scintillation vials at -80C prior to analysis | E4: Chlorophyll samples were filtered onto 25mm GF/F filters and stored in glass scintillation vials at -80C prior to analysis | F4: Chlorophyll samples were filtered onto 25mm GF/F filters and stored in glass scintillation vials at -80C prior to analysis | G4: Chlorophyll samples were filtered onto 25mm GF/F filters and stored in glass scintillation vials at -80C prior to analysis
B5: Samples were extracted in 90% acetone at -20C for 24 +/-1 hours in the lab
B6: analyzed on a Turner Trilogy7200-000 flourometer calibrated with commercially pure chlorophyll a standard (Sigma)
B7: fluorescence readings taken before and after acidification were used to calculate chlorophyll and phaeopigment concentrations (Holm-Hansen et al 1965).
B8: Chlorophyll samples were analyzed at IOS in Room 2423, 15 weeks after the cruise.
B9: Variability is assessed as the %CV (std dev/mean*100) for duplicate samples.
B10: Chlorophyll values ranged from 0.00 - 0.81 ug/L in 414 samples. 71 of 414 samples were below Minimum Limit of Detection (<MLD). Samples <MLD that were collected in duplicate were not included in the %CV calculation. The original %CV for this dataset was 8.82% for 171 duplicate samples, excluding the average of duplicate pairs that were <MDL. 36 duplicates had a CV%>10, and 9 duplicates had a CV%>30. 10 duplicates were rejected (A or B), improving the %CV to 6.59% over 161 duplicate pairs, with 26 samples having a CV%>10 and 4 having a %CV>30. Our average dataset %CV is 3.89 % for 2013 - 2021 using the Turner 10-AU - so the overall quality of this dataset is acceptable.
B15: =Notes!A33 -> Minimum Limit of Detection (MLD): The stated MLD for the Turner Trilogy 7200-000 fluorometer is 0.025 ug/L for CHL-a. Samples below the MLD are reported as is and assigned Quality Flag 2 with an associated comment. Where samples are taken in duplicate and the average of the two is <MLD, the average value is reported as is and assigned Quality Flag 2 with an associated comment. Samples <MLD are excluded from precision (CV%) calculations.
A19: Cruise_Number | B19: Event_Number | C19: Station | D19: Sample_Number | E19: Chlorophyll:Extracted | F19: Flag:Chlorophyll:Extracted | G19: Phaeo-Pigment:Extracted | H19: Comments
A20: =$A$1 -> 2022-002 | B20: =VLOOKUP(D20,'Master List'!A4:G1633,7,FALSE) -> 8 | C20: =VLOOKUP(D20,'Master List'!$A$4:$G$1633,3,FALSE) -> 50-135 | D20: 4 | E20: 0.015479292 | F20: 26 | G20: 0.053007683 | H20: CHL: <Minimum Limit of Detection
A21: =$A$1 -> 2022-002 | B21: =VLOOKUP(D21,'Master List'!A5:G1634,7,FALSE) -> 8 | C21: =VLOOKUP(D21,'Master List'!$A$4:$G$1633,3,FALSE) -> 50-135 | D21: 6 | E21: 0.34011651 | F21: 6 | G21: 0.1586711
A22: =$A$1 -> 2022-002 | B22: =VLOOKUP(D22,'Master List'!A6:G1635,7,FALSE) -> 8 | C22: =VLOOKUP(D22,'Master List'!$A$4:$G$1633,3,FALSE) -> 50-135 | D22: 9 | E22: -99 | F22: 1 | G22: -99 | H22: CHL: Replicate A and B lost during sampling - no plastic grid put under filter.
A23: =$A$1 -> 2022-002 | B23: =VLOOKUP(D23,'Master List'!A6:G1635,7,FALSE) -> 8 | C23: =VLOOKUP(D23,'Master List'!$A$4:$G$1633,3,FALSE) -> 50-135 | D23: 12 | E23: 0.38544878 | F23: 6 | G23: 0.13023512
A24: =$A$1 -> 2022-002 | B24: =VLOOKUP(D24,'Master List'!A7:G1636,7,FALSE) -> 8 | C24: =VLOOKUP(D24,'Master List'!$A$4:$G$1633,3,FALSE) -> 50-135 | D24: 14 | E24: 0.3569263 | F24: 2 | G24: 0.11681006 | H24: CHL: Replicate A lost during sampling.
A25: =$A$1 -> 2022-002 | B25: =VLOOKUP(D25,'Master List'!A8:G1637,7,FALSE) -> 8 | C25: =VLOOKUP(D25,'Master List'!$A$4:$G$1633,3,FALSE) -> 50-135 | D25: 20 | E25: 0.37411783 | F25: 6 | G25: 0.11098976
A26: =$A$1 -> 2022-002 | B26: =VLOOKUP(D26,'Master List'!A9:G1638,7,FALSE) -> 12 | C26: =VLOOKUP(D26,'Master List'!$A$4:$G$1633,3,FALSE) -> 49-135 | D26: 24 | E26: 0.012908473 | F26: 26 | G26: 0.057730266 | H26: CHL: <Minimum Limit of Detection
A27: =$A$1 -> 2022-002 | B27: =VLOOKUP(D27,'Master List'!A10:G1639,7,FALSE) -> 12 | C27: =VLOOKUP(D27,'Master List'!$A$4:$G$1633,3,FALSE) -> 49-135 | D27: 28 | E27: 0.14639404 | F27: 6 | G27: 0.11451207
A28: =$A$1 -> 2022-002 | B28: =VLOOKUP(D28,'Master List'!A11:G1640,7,FALSE) -> 12 | C28: =VLOOKUP(D28,'Master List'!$A$4:$G$1633,3,FALSE) -> 49-135 | D28: 29 | E28: 0.31284473 | F28: 6 | G28: 0.12518718
A29: =$A$1 -> 2022-002 | B29: =VLOOKUP(D29,'Master List'!A12:G1641,7,FALSE) -> 12 | C29: =VLOOKUP(D29,'Master List'!$A$4:$G$1633,3,FALSE) -> 49-135 | D29: 32 | E29: 0.31540216 | F29: 36 | G29: 0.12403156 | H29: CHL: %CV>10
A30: =$A$1 -> 2022-002 | B30: =VLOOKUP(D30,'Master List'!A13:G1642,7,FALSE) -> 12 | C30: =VLOOKUP(D30,'Master List'!$A$4:$G$1633,3,FALSE) -> 49-135 | D30: 34 | E30: 0.33157362 | F30: 6 | G30: 0.1515768
A31: =$A$1 -> 2022-002 | B31: =VLOOKUP(D31,'Master List'!A14:G1643,7,FALSE) -> 12 | C31: =VLOOKUP(D31,'Master List'!$A$4:$G$1633,3,FALSE) -> 49-135 | D31: 40 | E31: 0.32681263 | F31: 6 | G31: 0.15307153
A32: =$A$1 -> 2022-002 | B32: =VLOOKUP(D32,'Master List'!A15:G1644,7,FALSE) -> 16 | C32: =VLOOKUP(D32,'Master List'!$A$4:$G$1633,3,FALSE) -> 48-135 | D32: 44 | E32: 0.010270159 | F32: 26 | G32: 0.073281275 | H32: CHL: <Minimum Limit of Detection
A33: =$A$1 -> 2022-002 | B33: =VLOOKUP(D33,'Master List'!A16:G1645,7,FALSE) -> 16 | C33: =VLOOKUP(D33,'Master List'!$A$4:$G$1633,3,FALSE) -> 48-135 | D33: 48 | E33: 0.22443567 | F33: 2 | G33: 0.21602546 | H33: CHL: duplicate 48A rejected.
A34: =$A$1 -> 2022-002 | B34: =VLOOKUP(D34,'Master List'!A17:G1646,7,FALSE) -> 16 | C34: =VLOOKUP(D34,'Master List'!$A$4:$G$1633,3,FALSE) -> 48-135 | D34: 49 | E34: 0.3860934 | F34: 6 | G34: 0.18665719
A35: =$A$1 -> 2022-002 | B35: =VLOOKUP(D35,'Master List'!A18:G1647,7,FALSE) -> 16 | C35: =VLOOKUP(D35,'Master List'!$A$4:$G$1633,3,FALSE) -> 48-135 | D35: 52 | E35: 0.3728704 | F35: 6 | G35: 0.15786997
A36: =$A$1 -> 2022-002 | B36: =VLOOKUP(D36,'Master List'!A19:G1648,7,FALSE) -> 16 | C36: =VLOOKUP(D36,'Master List'!$A$4:$G$1633,3,FALSE) -> 48-135 | D36: 54 | E36: 0.37247117 | F36: 6 | G36: 0.19025389
A37: =$A$1 -> 2022-002 | B37: =VLOOKUP(D37,'Master List'!A20:G1649,7,FALSE) -> 16 | C37: =VLOOKUP(D37,'Master List'!$A$4:$G$1633,3,FALSE) -> 48-135 | D37: 60 | E37: 0.37163418 | F37: 6 | G37: 0.14825419
A38: =$A$1 -> 2022-002 | B38: =VLOOKUP(D38,'Master List'!A21:G1650,7,FALSE) -> 20 | C38: =VLOOKUP(D38,'Master List'!$A$4:$G$1633,3,FALSE) -> 47-135 | D38: 64 | E38: 0.016278574 | F38: 26 | G38: 0.056175327 | H38: CHL: <Minimum Limit of Detection
A39: =$A$1 -> 2022-002 | B39: =VLOOKUP(D39,'Master List'!A22:G1651,7,FALSE) -> 20 | C39: =VLOOKUP(D39,'Master List'!$A$4:$G$1633,3,FALSE) -> 47-135 | D39: 68 | E39: 0.19634193 | F39: 6 | G39: 0.12595364
A40: =$A$1 -> 2022-002 | B40: =VLOOKUP(D40,'Master List'!A23:G1652,7,FALSE) -> 20 | C40: =VLOOKUP(D40,'Master List'!$A$4:$G$1633,3,FALSE) -> 47-135 | D40: 69 | E40: 0.3475691 | F40: 6 | G40: 0.26647672
A41: =$A$1 -> 2022-002 | B41: =VLOOKUP(D41,'Master List'!A24:G1653,7,FALSE) -> 20 | C41: =VLOOKUP(D41,'Master List'!$A$4:$G$1633,3,FALSE) -> 47-135 | D41: 72 | E41: 0.37376369 | F41: 6 | G41: 0.18459353
A42: =$A$1 -> 2022-002 | B42: =VLOOKUP(D42,'Master List'!A25:G1654,7,FALSE) -> 20 | C42: =VLOOKUP(D42,'Master List'!$A$4:$G$1633,3,FALSE) -> 47-135 | D42: 74 | E42: 0.35813683 | F42: 6 | G42: 0.1624975
A43: =$A$1 -> 2022-002 | B43: =VLOOKUP(D43,'Master List'!A26:G1655,7,FALSE) -> 20 | C43: =VLOOKUP(D43,'Master List'!$A$4:$G$1633,3,FALSE) -> 47-135 | D43: 80 | E43: 0.34573143 | F43: 6 | G43: 0.14327783
A44: =$A$1 -> 2022-002 | B44: =VLOOKUP(D44,'Master List'!A27:G1656,7,FALSE) -> 24 | C44: =VLOOKUP(D44,'Master List'!$A$4:$G$1633,3,FALSE) -> 47-138 | D44: 84 | E44: 0.017767015 | F44: 26 | G44: 0.051381427 | H44: CHL: <Minimum Limit of Detection
A45: =$A$1 -> 2022-002 | B45: =VLOOKUP(D45,'Master List'!A28:G1657,7,FALSE) -> 24 | C45: =VLOOKUP(D45,'Master List'!$A$4:$G$1633,3,FALSE) -> 47-138 | D45: 88 | E45: 0.091699375 | F45: 6 | G45: 0.090406922
A46: =$A$1 -> 2022-002 | B46: =VLOOKUP(D46,'Master List'!A29:G1658,7,FALSE) -> 24 | C46: =VLOOKUP(D46,'Master List'!$A$4:$G$1633,3,FALSE) -> 47-138 | D46: 89 | E46: 0.13118992 | F46: 2 | G46: 0.12521337 | H46: CHL: duplicate 89B rejected.
A47: =$A$1 -> 2022-002 | B47: =VLOOKUP(D47,'Master List'!A30:G1659,7,FALSE) -> 24 | C47: =VLOOKUP(D47,'Master List'!$A$4:$G$1633,3,FALSE) -> 47-138 | D47: 92 | E47: 0.44670958 | F47: 6 | G47: 0.19404491
A48: =$A$1 -> 2022-002 | B48: =VLOOKUP(D48,'Master List'!A31:G1660,7,FALSE) -> 24 | C48: =VLOOKUP(D48,'Master List'!$A$4:$G$1633,3,FALSE) -> 47-138 | D48: 94 | E48: 0.42970906 | F48: 36 | G48: 0.19233328 | H48: CHL: %CV>10
...

Sheet CV% 
A1: =Notes!A1 -> 2022-002
A2: Calculating CV % for duplicate pairs and Overall CV% for dataset | N2: Chl min | O2: =MIN(I:I) -> 0.0030993015
A3: Average of two samples is reported. | N3: Chl max | O3: =MAX(I:I) -> 0.81262965
A4: When samples Chl.a is below Minimum Detection Limit, the CV% is not calculated and is excluded from the CV% calculation and precsision statement. | N4: # Dups | O4: =COUNT(I:I) -> 195
A5: When average of 2 samples is below minimum detectable limit (<MDL), the Chlorophyll: extracted is reported as-is, Quality Flag is 2 with an associated comment. | N5: %CV >10 | O5: =COUNTIF(H:H,">10") -> 36
A6: When duplicate pair CV % is greater than 10 %, Quality Flag is 3 with an associated comment . | N6: CHL: %CV>30 | O6: =COUNTIF(H:H,">30") -> 9
A7: When duplicate pair CV % is greater than 30 %, Quality Flag is 4 with an associated comment. | N7: %CV Avg | O7: =AVERAGE(H:H) -> 8.8230644
N8: # Rejected | O8: {=(SUMPRODUCT((LEN(L:L)-LEN(SUBSTITUTE((UPPER(L:L)),UPPER("rejected"),"")))/LEN("rejected")))/2} -> 10
A9: Station | B9: Sample_Number | C9: Duplicate | D9: Chl.a | E9: Phaeo | F9: diff | G9: diff^2 | H9: CV% (chl) | I9: Chlorophyll:Extracted | J9: Phaeo-Pigment:Extracted | K9: Flag:Chlorophyll:Extracted | L9: Comments | N9: # <MLD | O9: =((COUNTIFS(D:D,"<0.025"))-(COUNTIF(D:D,-99))) -> 71
A10: =VLOOKUP(B10,'Master List'!$A$4:$C$1633,3,FALSE) -> 50-135 | B10: 4 | C10: A | D10: 0.016513577 | E10: 0.060992169 | I10: =AVERAGE(D10:D11) -> 0.015479292 | J10: =AVERAGE(E10:E11) -> 0.053007683 | K10: 26 | L10: CHL: <Minimum Limit of Detection
A11: =VLOOKUP(B11,'Master List'!$A$4:$C$1633,3,FALSE) -> 50-135 | B11: 4 | C11: B | D11: 0.014445008 | E11: 0.045023197
A12: =VLOOKUP(B12,'Master List'!$A$4:$C$1633,3,FALSE) -> 50-135 | B12: 6 | C12: A | D12: 0.33050763 | E12: 0.2327728 | F12: =(D12-D13) -> -0.019217746 | G12: =F12^2 -> 0.00036932177 | H12: =(_xlfn.STDEV.S(D12:D13)/AVERAGE(D12:D13))*100 -> 3.9953952 | I12: =AVERAGE(D12:D13) -> 0.34011651 | J12: =AVERAGE(E12:E13) -> 0.1586711 | K12: 6
A13: =VLOOKUP(B13,'Master List'!$A$4:$C$1633,3,FALSE) -> 50-135 | B13: 6 | C13: B | D13: 0.34972538 | E13: 0.084569409
A14: =VLOOKUP(B14,'Master List'!$A$4:$C$1633,3,FALSE) -> 50-135 | B14: 9 | C14: A | D14: -99 | E14: -99 | K14: 1 | L14: Replicate A and B lost during sampling - no plastic grid put under filter.
A15: =VLOOKUP(B15,'Master List'!$A$4:$C$1633,3,FALSE) -> 50-135 | B15: 9 | C15: B | D15: -99 | E15: -99
A16: =VLOOKUP(B16,'Master List'!$A$4:$C$1633,3,FALSE) -> 50-135 | B16: 12 | C16: A | D16: 0.40651512 | E16: 0.13428669 | F16: =(D16-D17) -> 0.042132684 | G16: =F16^2 -> 0.0017751631 | H16: =(_xlfn.STDEV.S(D16:D17)/AVERAGE(D16:D17))*100 -> 7.7292518 | I16: =AVERAGE(D16:D17) -> 0.38544878 | J16: =AVERAGE(E16:E17) -> 0.13023512 | K16: 6
A17: =VLOOKUP(B17,'Master List'!$A$4:$C$1633,3,FALSE) -> 50-135 | B17: 12 | C17: B | D17: 0.36438244 | E17: 0.12618354
A18: =VLOOKUP(B18,'Master List'!$A$4:$C$1633,3,FALSE) -> 50-135 | B18: 14 | C18: A | D18: -99 | E18: -99 | K18: 2 | L18: Replicate A lost during sampling.
A19: =VLOOKUP(B19,'Master List'!$A$4:$C$1633,3,FALSE) -> 50-135 | B19: 14 | C19: B | D19: 0.3569263 | E19: 0.11681006
A20: =VLOOKUP(B20,'Master List'!$A$4:$C$1633,3,FALSE) -> 50-135 | B20: 20 | C20: A | D20: 0.39112901 | E20: 0.11847258 | F20: =(D20-D21) -> 0.034022363 | G20: =F20^2 -> 0.0011575212 | H20: =(_xlfn.STDEV.S(D20:D21)/AVERAGE(D20:D21))*100 -> 6.4304455 | I20: =AVERAGE(D20:D21) -> 0.37411783 | J20: =AVERAGE(E20:E21) -> 0.11098976 | K20: 6
A21: =VLOOKUP(B21,'Master List'!$A$4:$C$1633,3,FALSE) -> 50-135 | B21: 20 | C21: B | D21: 0.35710665 | E21: 0.10350693
A22: =VLOOKUP(B22,'Master List'!$A$4:$C$1633,3,FALSE) -> 49-135 | B22: 24 | C22: A | D22: 0.019047233 | E22: 0.045190672 | I22: =AVERAGE(D22:D23) -> 0.012908473 | J22: =AVERAGE(E22:E23) -> 0.057730266 | K22: 26 | L22: CHL: <Minimum Limit of Detection
A23: =VLOOKUP(B23,'Master List'!$A$4:$C$1633,3,FALSE) -> 49-135 | B23: 24 | C23: B | D23: 0.006769714 | E23: 0.070269859
A24: =VLOOKUP(B24,'Master List'!$A$4:$C$1633,3,FALSE) -> 49-135 | B24: 28 | C24: A | D24: 0.14669353 | E24: 0.10274487 | F24: =(D24-D25) -> 0.00059898333 | G24: =F24^2 -> 3.5878103e-07 | H24: =(_xlfn.STDEV.S(D24:D25)/AVERAGE(D24:D25))*100 -> 0.28931859 | I24: =AVERAGE(D24:D25) -> 0.14639404 | J24: =AVERAGE(E24:E25) -> 0.11451207 | K24: 6
A25: =VLOOKUP(B25,'Master List'!$A$4:$C$1633,3,FALSE) -> 49-135 | B25: 28 | C25: B | D25: 0.14609455 | E25: 0.12627926
A26: =VLOOKUP(B26,'Master List'!$A$4:$C$1633,3,FALSE) -> 49-135 | B26: 29 | C26: A | D26: 0.31030998 | E26: 0.11582796 | F26: =(D26-D27) -> -0.0050694976 | G26: =F26^2 -> 2.5699806e-05 | H26: =(_xlfn.STDEV.S(D26:D27)/AVERAGE(D26:D27))*100 -> 1.1458324 | I26: =AVERAGE(D26:D27) -> 0.31284473 | J26: =AVERAGE(E26:E27) -> 0.12518718 | K26: 6
A27: =VLOOKUP(B27,'Master List'!$A$4:$C$1633,3,FALSE) -> 49-135 | B27: 29 | C27: B | D27: 0.31537948 | E27: 0.13454641
A28: =VLOOKUP(B28,'Master List'!$A$4:$C$1633,3,FALSE) -> 49-135 | B28: 32 | C28: A | D28: 0.29088729 | E28: 0.13036688 | F28: =(D28-D29) -> -0.049029737 | G28: =F28^2 -> 0.0024039151 | H28: =(_xlfn.STDEV.S(D28:D29)/AVERAGE(D28:D29))*100 -> 10.992081 | I28: =AVERAGE(D28:D29) -> 0.31540216 | J28: =AVERAGE(E28:E29) -> 0.12403156 | K28: 36 | L28: CHL: %CV>10
A29: =VLOOKUP(B29,'Master List'!$A$4:$C$1633,3,FALSE) -> 49-135 | B29: 32 | C29: B | D29: 0.33991703 | E29: 0.11769624
A30: =VLOOKUP(B30,'Master List'!$A$4:$C$1633,3,FALSE) -> 49-135 | B30: 34 | C30: A | D30: 0.31928927 | E30: 0.15296877 | F30: =(D30-D31) -> -0.0245687 | G30: =F30^2 -> 0.00060362104 | H30: =(_xlfn.STDEV.S(D30:D31)/AVERAGE(D30:D31))*100 -> 5.2394683 | I30: =AVERAGE(D30:D31) -> 0.33157362 | J30: =AVERAGE(E30:E31) -> 0.1515768 | K30: 6
A31: =VLOOKUP(B31,'Master List'!$A$4:$C$1633,3,FALSE) -> 49-135 | B31: 34 | C31: B | D31: 0.34385797 | E31: 0.15018482
A32: =VLOOKUP(B32,'Master List'!$A$4:$C$1633,3,FALSE) -> 49-135 | B32: 40 | C32: A | D32: 0.34833996 | E32: 0.1516659 | F32: =(D32-D33) -> 0.04305466 | G32: =F32^2 -> 0.0018537037 | H32: =(_xlfn.STDEV.S(D32:D33)/AVERAGE(D32:D33))*100 -> 9.3155034 | I32: =AVERAGE(D32:D33) -> 0.32681263 | J32: =AVERAGE(E32:E33) -> 0.15307153 | K32: 6
A33: =VLOOKUP(B33,'Master List'!$A$4:$C$1633,3,FALSE) -> 49-135 | B33: 40 | C33: B | D33: 0.3052853 | E33: 0.15447715
A34: =VLOOKUP(B34,'Master List'!$A$4:$C$1633,3,FALSE) -> 48-135 | B34: 44 | C34: A | D34: 0.012822397 | E34: 0.063896067 | I34: =AVERAGE(D34:D35) -> 0.010270159 | J34: =AVERAGE(E34:E35) -> 0.073281275 | K34: 26 | L34: CHL: <Minimum Limit of Detection
A35: =VLOOKUP(B35,'Master List'!$A$4:$C$1633,3,FALSE) -> 48-135 | B35: 44 | C35: B | D35: 0.0077179221 | E35: 0.082666483
A36: =VLOOKUP(B36,'Master List'!$A$4:$C$1633,3,FALSE) -> 48-135 | B36: 48 | C36: A | D36: 0.37529093 | E36: 0.080928518 | F36: =(D36-D37) -> 0.15085526 | G36: =F36^2 -> 0.022757311 | H36: =(_xlfn.STDEV.S(D36:D37)/AVERAGE(D36:D37))*100 -> 35.573136 | K36: 2 | L36: CHL: rejected duplicate 48A
A37: =VLOOKUP(B37,'Master List'!$A$4:$C$1633,3,FALSE) -> 48-135 | B37: 48 | C37: B | D37: 0.22443567 | E37: 0.21602546 | L37: CHL: duplicate 48A rejected. 48A - filter was essentially disintegrated after extraction, and CHL concentration for 48B agrees with the CTD fluorometer best (at 0.17 ug/L).
A38: =VLOOKUP(B38,'Master List'!$A$4:$C$1633,3,FALSE) -> 48-135 | B38: 49 | C38: A | D38: 0.39488523 | E38: 0.19460273 | F38: =(D38-D39) -> 0.017583658 | G38: =F38^2 -> 0.00030918505 | H38: =(_xlfn.STDEV.S(D38:D39)/AVERAGE(D38:D39))*100 -> 3.220341 | I38: =AVERAGE(D38:D39) -> 0.3860934 | J38: =AVERAGE(E38:E39) -> 0.18665719 | K38: 6
A39: =VLOOKUP(B39,'Master List'!$A$4:$C$1633,3,FALSE) -> 48-135 | B39: 49 | C39: B | D39: 0.37730157 | E39: 0.17871164
A40: =VLOOKUP(B40,'Master List'!$A$4:$C$1633,3,FALSE) -> 48-135 | B40: 52 | C40: A | D40: 0.36586733 | E40: 0.14913116 | F40: =(D40-D41) -> -0.014006154 | G40: =F40^2 -> 0.00019617235 | H40: =(_xlfn.STDEV.S(D40:D41)/AVERAGE(D40:D41))*100 -> 2.6561096 | I40: =AVERAGE(D40:D41) -> 0.3728704 | J40: =AVERAGE(E40:E41) -> 0.15786997 | K40: 6
...

Sheet Raw Data
A1: =Notes!A1 -> 2022-002 | I1: Summary
A2: Model: | B2: Turner Trilogy 7200-000(blue) | I2: CHL min | J2: ='CV% '!O2 -> 0.0030993015
A3: Module: | B3: WP #2 old module | I3: CHL Max | J3: ='CV% '!O3 -> 0.81262965
A4: SN: | B4: 720 222 180 | I4: CHL average | J4: =AVERAGEIF(P12:P431,">-.01") -> 0.25690001
A5: Analysis: | B5: Hayleigh Shannon | I5: # samples | J5: =COUNT(CHL!E20:E229) -> 210
A6: Calibration : | B6: February 10, 2022: Chl-a (ug/L) = .0007677*(1.859/(1.859-1))*(Fo-Fa)*(vol-ex / vol-filt)*(dilution factor) | I6: #Dups | J6: ='CV% '!O4 -> 195
B7: February 10, 2022: Phaeo(ug/L) = .0007677*(1.859/(1.859-1))*((1.859*Fa)-Fo)*(vol-ex / vol-filt)*(dilution factor) | I7: %CV | J7: ='CV% '!O7 -> 8.8230644
A8: Avge Tau | B8: 1.8585929
A9: Slope | B9: 0.00076766546
J10: Turner Trilogy
A11: Analyzed_Date | B11: Station | C11: Sample_Number | D11: Duplicate | E11: Depth (dbar) | F11: CTD fluor | G11: Volume Filtered (mL) | H11: Vol.acet. (mL) | I11: Dilution factor | J11: Before acid | K11: After acid | L11: Before acid blank | M11: After acid blank | N11: Blank Corrected Before | O11: Blank Corrected After | P11: Chl a ug/L | Q11: Phaeo ug/L | R11: Ratio Rb/Ra | S11: notes | T11: ORDER
A12: 44750 | B12: =VLOOKUP(C12,'Master List'!A:C,3,FALSE) -> 50-135 | C12: 4 | D12: A | E12: =VLOOKUP(C12,'Master List'!A:G,5,FALSE) -> 150 | F12: =VLOOKUP(C12,'2022-002-bottles_csv'!E:L,8,FALSE) -> 0.09 | G12: 304 | H12: 10 | I12: 1 | J12: 2258.26 | K12: 1957.37 | L12: 305.14 | M12: 306.41 | N12: =J12-L12 -> 1953.12 | O12: =K12-M12 -> 1650.96 | P12: =0.0007677*(1.859/(1.859-1))*(N12-O12)*(H12/G12)*I12 -> 0.016513577 | Q12: =0.0007677*(1.859/(1.859-1))*((1.859*O12)-N12)*(H12/G12)*I12 -> 0.060992169 | R12: =N12/O12 -> 1.1830208 | T12: 120
A13: 44755 | B13: =VLOOKUP(C13,'Master List'!A:C,3,FALSE) -> 50-135 | C13: 4 | D13: B | E13: =VLOOKUP(C13,'Master List'!A:G,5,FALSE) -> 150 | F13: =VLOOKUP(C13,'2022-002-bottles_csv'!E:L,8,FALSE) -> 0.09 | G13: 304 | H13: 10 | I13: 1 | J13: 1863.47 | K13: 1614.78 | L13: 332.42 | M13: 348.04 | N13: =J13-L13 -> 1531.05 | O13: =K13-M13 -> 1266.74 | P13: =0.0007677*(1.859/(1.859-1))*(N13-O13)*(H13/G13)*I13 -> 0.014445008 | Q13: =0.0007677*(1.859/(1.859-1))*((1.859*O13)-N13)*(H13/G13)*I13 -> 0.045023197 | R13: =N13/O13 -> 1.2086537 | T13: 219
A14: 44750 | B14: =VLOOKUP(C14,'Master List'!A:C,3,FALSE) -> 50-135 | C14: 6 | D14: A | E14: =VLOOKUP(C14,'Master List'!A:G,5,FALSE) -> 100 | F14: =VLOOKUP(C14,'2022-002-bottles_csv'!E:L,8,FALSE) -> 0.18 | G14: 304 | H14: 10 | I14: 1 | J14: 18351.17 | K14: 12304.92 | L14: 305.14 | M14: 306.41 | N14: =J14-L14 -> 18046.03 | O14: =K14-M14 -> 11998.51 | P14: =0.0007677*(1.859/(1.859-1))*(N14-O14)*(H14/G14)*I14 -> 0.33050763 | Q14: =0.0007677*(1.859/(1.859-1))*((1.859*O14)-N14)*(H14/G14)*I14 -> 0.2327728 | R14: =N14/O14 -> 1.5040226 | T14: 116
A15: 44756 | B15: =VLOOKUP(C15,'Master List'!A:C,3,FALSE) -> 50-135 | C15: 6 | D15: B | E15: =VLOOKUP(C15,'Master List'!A:G,5,FALSE) -> 100 | F15: =VLOOKUP(C15,'2022-002-bottles_csv'!E:L,8,FALSE) -> 0.18 | G15: 304 | H15: 10 | I15: 1 | J15: 15982.29 | K15: 9595.12 | L15: 332.16 | M15: 344.15 | N15: =J15-L15 -> 15650.13 | O15: =K15-M15 -> 9250.97 | P15: =0.0007677*(1.859/(1.859-1))*(N15-O15)*(H15/G15)*I15 -> 0.34972538 | Q15: =0.0007677*(1.859/(1.859-1))*((1.859*O15)-N15)*(H15/G15)*I15 -> 0.084569409 | R15: =N15/O15 -> 1.6917285 | T15: 242
A16: NA | B16: =VLOOKUP(C16,'Master List'!A:C,3,FALSE) -> 50-135 | C16: 9 | D16: A | E16: =VLOOKUP(C16,'Master List'!A:G,5,FALSE) -> 75 | F16: =VLOOKUP(C16,'2022-002-bottles_csv'!E:L,8,FALSE) -> 0.19 | P16: -99 | Q16: -99 | S16: Sampling comment: 9A lost on board
A17: NA | B17: =VLOOKUP(C17,'Master List'!A:C,3,FALSE) -> 50-135 | C17: 9 | D17: B | E17: =VLOOKUP(C17,'Master List'!A:G,5,FALSE) -> 75 | F17: =VLOOKUP(C17,'2022-002-bottles_csv'!E:L,8,FALSE) -> 0.19 | P17: -99 | Q17: -99 | S17: Sampling comment: 9A lost on board
A18: 44750 | B18: =VLOOKUP(C18,'Master List'!A:C,3,FALSE) -> 50-135 | C18: 12 | D18: A | E18: =VLOOKUP(C18,'Master List'!A:G,5,FALSE) -> 50 | F18: =VLOOKUP(C18,'2022-002-bottles_csv'!E:L,8,FALSE) -> 0.21 | G18: 304 | H18: 10 | I18: 1 | J18: 19263.11 | K18: 11826.1 | L18: 305.14 | M18: 306.41 | N18: =J18-L18 -> 18957.97 | O18: =K18-M18 -> 11519.69 | P18: =0.0007677*(1.859/(1.859-1))*(N18-O18)*(H18/G18)*I18 -> 0.40651512 | Q18: =0.0007677*(1.859/(1.859-1))*((1.859*O18)-N18)*(H18/G18)*I18 -> 0.13428669 | R18: =N18/O18 -> 1.6457014 | T18: 118
A19: 44761 | B19: =VLOOKUP(C19,'Master List'!A:C,3,FALSE) -> 50-135 | C19: 12 | D19: B | E19: =VLOOKUP(C19,'Master List'!A:G,5,FALSE) -> 50 | F19: =VLOOKUP(C19,'2022-002-bottles_csv'!E:L,8,FALSE) -> 0.21 | G19: 304 | H19: 10 | I19: 1 | J19: 17451.83 | K19: 10783.43 | L19: 334.87 | M19: 333.82 | N19: =J19-L19 -> 17116.96 | O19: =K19-M19 -> 10449.61 | P19: =0.0007677*(1.859/(1.859-1))*(N19-O19)*(H19/G19)*I19 -> 0.36438244 | Q19: =0.0007677*(1.859/(1.859-1))*((1.859*O19)-N19)*(H19/G19)*I19 -> 0.12618354 | R19: =N19/O19 -> 1.6380477 | T19: 400
A20: NA | B20: =VLOOKUP(C20,'Master List'!A:C,3,FALSE) -> 50-135 | C20: 14 | D20: A | E20: =VLOOKUP(C20,'Master List'!A:G,5,FALSE) -> 25 | F20: =VLOOKUP(C20,'2022-002-bottles_csv'!E:L,8,FALSE) -> 0.19 | P20: -99 | Q20: -99 | S20: Sampling comment: 9A lost on board
A21: 44757 | B21: =VLOOKUP(C21,'Master List'!A:C,3,FALSE) -> 50-135 | C21: 14 | D21: B | E21: =VLOOKUP(C21,'Master List'!A:G,5,FALSE) -> 25 | F21: =VLOOKUP(C21,'2022-002-bottles_csv'!E:L,8,FALSE) -> 0.19 | G21: 304 | H21: 10 | I21: 1 | J21: 16927.5 | K21: 10409.81 | L21: 305.46 | M21: 318.69 | N21: =J21-L21 -> 16622.04 | O21: =K21-M21 -> 10091.12 | P21: =0.0007677*(1.859/(1.859-1))*(N21-O21)*(H21/G21)*I21 -> 0.3569263 | Q21: =0.0007677*(1.859/(1.859-1))*((1.859*O21)-N21)*(H21/G21)*I21 -> 0.11681006 | R21: =N21/O21 -> 1.6471948 | T21: 302
A22: 44750 | B22: =VLOOKUP(C22,'Master List'!A:C,3,FALSE) -> 50-135 | C22: 20 | D22: A | E22: =VLOOKUP(C22,'Master List'!A:G,5,FALSE) -> 5 | F22: =VLOOKUP(C22,'2022-002-bottles_csv'!E:L,8,FALSE) -> 0.13 | G22: 304 | H22: 10 | I22: 1 | J22: 18316.98 | K22: 11161.5 | L22: 305.14 | M22: 306.41 | N22: =J22-L22 -> 18011.84 | O22: =K22-M22 -> 10855.09 | P22: =0.0007677*(1.859/(1.859-1))*(N22-O22)*(H22/G22)*I22 -> 0.39112901 | Q22: =0.0007677*(1.859/(1.859-1))*((1.859*O22)-N22)*(H22/G22)*I22 -> 0.11847258 | R22: =N22/O22 -> 1.659299 | T22: 114
A23: 44756 | B23: =VLOOKUP(C23,'Master List'!A:C,3,FALSE) -> 50-135 | C23: 20 | D23: B | E23: =VLOOKUP(C23,'Master List'!A:G,5,FALSE) -> 5 | F23: =VLOOKUP(C23,'2022-002-bottles_csv'!E:L,8,FALSE) -> 0.13 | G23: 304 | H23: 10 | I23: 1 | J23: 16677.97 | K23: 10155.74 | L23: 332.16 | M23: 344.15 | N23: =J23-L23 -> 16345.81 | O23: =K23-M23 -> 9811.59 | P23: =0.0007677*(1.859/(1.859-1))*(N23-O23)*(H23/G23)*I23 -> 0.35710665 | Q23: =0.0007677*(1.859/(1.859-1))*((1.859*O23)-N23)*(H23/G23)*I23 -> 0.10350693 | R23: =N23/O23 -> 1.6659695 | T23: 260
A24: 44750 | B24: =VLOOKUP(C24,'Master List'!A:C,3,FALSE) -> 49-135 | C24: 24 | D24: A | E24: =VLOOKUP(C24,'Master List'!A:G,5,FALSE) -> 150 | F24: =VLOOKUP(C24,'2022-002-bottles_csv'!E:L,8,FALSE) -> 0.08 | G24: 304 | H24: 10 | I24: 1 | J24: 1969.8 | K24: 1631.32 | L24: 252.94 | M24: 262.98 | N24: =J24-L24 -> 1716.86 | O24: =K24-M24 -> 1368.34 | P24: =0.0007677*(1.859/(1.859-1))*(N24-O24)*(H24/G24)*I24 -> 0.019047233 | Q24: =0.0007677*(1.859/(1.859-1))*((1.859*O24)-N24)*(H24/G24)*I24 -> 0.045190672 | R24: =N24/O24 -> 1.2547028 | T24: 132
A25: 44755 | B25: =VLOOKUP(C25,'Master List'!A:C,3,FALSE) -> 49-135 | C25: 24 | D25: B | E25: =VLOOKUP(C25,'Master List'!A:G,5,FALSE) -> 150 | F25: =VLOOKUP(C25,'2022-002-bottles_csv'!E:L,8,FALSE) -> 0.08 | G25: 304 | H25: 10 | I25: 1 | J25: 2076.29 | K25: 1939.56 | L25: 311.39 | M25: 298.53 | N25: =J25-L25 -> 1764.9 | O25: =K25-M25 -> 1641.03 | P25: =0.0007677*(1.859/(1.859-1))*(N25-O25)*(H25/G25)*I25 -> 0.006769714 | Q25: =0.0007677*(1.859/(1.859-1))*((1.859*O25)-N25)*(H25/G25)*I25 -> 0.070269859 | R25: =N25/O25 -> 1.0754831 | T25: 211
A26: 44754 | B26: =VLOOKUP(C26,'Master List'!A:C,3,FALSE) -> 49-135 | C26: 28 | D26: A | E26: =VLOOKUP(C26,'Master List'!A:G,5,FALSE) -> 100 | F26: =VLOOKUP(C26,'2022-002-bottles_csv'!E:L,8,FALSE) -> 0.12 | G26: 304 | H26: 10 | I26: 1 | J26: 8293.73 | K26: 5622.19 | L26: 296.26 | M26: 308.87 | N26: =J26-L26 -> 7997.47 | O26: =K26-M26 -> 5313.32 | P26: =0.0007677*(1.859/(1.859-1))*(N26-O26)*(H26/G26)*I26 -> 0.14669353 | Q26: =0.0007677*(1.859/(1.859-1))*((1.859*O26)-N26)*(H26/G26)*I26 -> 0.10274487 | R26: =N26/O26 -> 1.5051738 | T26: 162
A27: 44757 | B27: =VLOOKUP(C27,'Master List'!A:C,3,FALSE) -> 49-135 | C27: 28 | D27: B | E27: =VLOOKUP(C27,'Master List'!A:G,5,FALSE) -> 100 | F27: =VLOOKUP(C27,'2022-002-bottles_csv'!E:L,8,FALSE) -> 0.12 | G27: 304 | H27: 10 | I27: 1 | J27: 8780.52 | K27: 6120.56 | L27: 305.46 | M27: 318.69 | N27: =J27-L27 -> 8475.06 | O27: =K27-M27 -> 5801.87 | P27: =0.0007677*(1.859/(1.859-1))*(N27-O27)*(H27/G27)*I27 -> 0.14609455 | Q27: =0.0007677*(1.859/(1.859-1))*((1.859*O27)-N27)*(H27/G27)*I27 -> 0.12627926 | R27: =N27/O27 -> 1.4607463 | T27: 290
A28: 44754 | B28: =VLOOKUP(C28,'Master List'!A:C,3,FALSE) -> 49-135 | C28: 29 | D28: A | E28: =VLOOKUP(C28,'Master List'!A:G,5,FALSE) -> 75 | F28: =VLOOKUP(C28,'2022-002-bottles_csv'!E:L,8,FALSE) -> 0.19 | G28: 304 | H28: 10 | I28: 1 | J28: 15051.43 | K28: 9386.09 | L28: 296.26 | M28: 308.87 | N28: =J28-L28 -> 14755.17 | O28: =K28-M28 -> 9077.22 | P28: =0.0007677*(1.859/(1.859-1))*(N28-O28)*(H28/G28)*I28 -> 0.31030998 | Q28: =0.0007677*(1.859/(1.859-1))*((1.859*O28)-N28)*(H28/G28)*I28 -> 0.11582796 | R28: =N28/O28 -> 1.6255164 | T28: 146
A29: 44756 | B29: =VLOOKUP(C29,'Master List'!A:C,3,FALSE) -> 49-135 | C29: 29 | D29: B | E29: =VLOOKUP(C29,'Master List'!A:G,5,FALSE) -> 75 | F29: =VLOOKUP(C29,'2022-002-bottles_csv'!E:L,8,FALSE) -> 0.19 | G29: 304 | H29: 10 | I29: 1 | J29: 15686.8 | K29: 9928.08 | L29: 332.16 | M29: 344.15 | N29: =J29-L29 -> 15354.64 | O29: =K29-M29 -> 9583.93 | P29: =0.0007677*(1.859/(1.859-1))*(N29-O29)*(H29/G29)*I29 -> 0.31537948 | Q29: =0.0007677*(1.859/(1.859-1))*((1.859*O29)-N29)*(H29/G29)*I29 -> 0.13454641 | R29: =N29/O29 -> 1.6021236 | T29: 245
A30: 44754 | B30: =VLOOKUP(C30,'Master List'!A:C,3,FALSE) -> 49-135 | C30: 32 | D30: A | E30: =VLOOKUP(C30,'Master List'!A:G,5,FALSE) -> 50 | F30: =VLOOKUP(C30,'2022-002-bottles_csv'!E:L,8,FALSE) -> 0.21 | G30: 304 | H30: 10 | I30: 1 | J30: 14592.01 | K30: 9282.06 | L30: 296.26 | M30: 308.87 | N30: =J30-L30 -> 14295.75 | O30: =K30-M30 -> 8973.19 | P30: =0.0007677*(1.859/(1.859-1))*(N30-O30)*(H30/G30)*I30 -> 0.29088729 | Q30: =0.0007677*(1.859/(1.859-1))*((1.859*O30)-N30)*(H30/G30)*I30 -> 0.13036688 | R30: =N30/O30 -> 1.5931625 | T30: 147
A31: 44755 | B31: =VLOOKUP(C31,'Master List'!A:C,3,FALSE) -> 49-135 | C31: 32 | D31: B | E31: =VLOOKUP(C31,'Master List'!A:G,5,FALSE) -> 50 | F31: =VLOOKUP(C31,'2022-002-bottles_csv'!E:L,8,FALSE) -> 0.21 | G31: 304 | H31: 10 | I31: 1 | J31: 16299.79 | K31: 10095.72 | L31: 332.42 | M31: 348.04 | N31: =J31-L31 -> 15967.37 | O31: =K31-M31 -> 9747.68 | P31: =0.0007677*(1.859/(1.859-1))*(N31-O31)*(H31/G31)*I31 -> 0.33991703 | Q31: =0.0007677*(1.859/(1.859-1))*((1.859*O31)-N31)*(H31/G31)*I31 -> 0.11769624 | R31: =N31/O31 -> 1.6380688 | T31: 231
A32: 44750 | B32: =VLOOKUP(C32,'Master List'!A:C,3,FALSE) -> 49-135 | C32: 34 | D32: A | E32: =VLOOKUP(C32,'Master List'!A:G,5,FALSE) -> 25 | F32: =VLOOKUP(C32,'2022-002-bottles_csv'!E:L,8,FALSE) -> 0.22 | G32: 304 | H32: 10 | I32: 1 | J32: 16154.82 | K32: 10322.61 | L32: 252.94 | M32: 262.98 | N32: =J32-L32 -> 15901.88 | O32: =K32-M32 -> 10059.63 | P32: =0.0007677*(1.859/(1.859-1))*(N32-O32)*(H32/G32)*I32 -> 0.31928927 | Q32: =0.0007677*(1.859/(1.859-1))*((1.859*O32)-N32)*(H32/G32)*I32 -> 0.15296877 | R32: =N32/O32 -> 1.5807619 | T32: 128
... A37: 44761 | B37: =VLOOKUP(C37,'Master List'!A:C,3,FALSE) -> 48-135 | C37: 44 | D37: B | E37: =VLOOKUP(C37,'Master List'!A:G,5,FALSE) -> 150 | F37: =VLOOKUP(C37,'2022-002-bottles_csv'!E:L,8,FALSE) -> 0.07 | G37: 304 | H37: 10 | I37: 1 | J37: 2428.55 | K37: 2289.22 | L37: 362.04 | M37: 363.93 | N37: =J37-L37 -> 2066.51 | O37: =K37-M37 -> 1925.29 | P37: =0.0007677*(1.859/(1.859-1))*(N37-O37)*(H37/G37)*I37 -> 0.0077179221 | Q37: =0.0007677*(1.859/(1.859-1))*((1.859*O37)-N37)*(H37/G37)*I37 -> 0.082666483 | R37: =N37/O37 -> 1.07335 | T37: 387
A38: 44754 | B38: =VLOOKUP(C38,'Master List'!A:C,3,FALSE) -> 48-135 | C38: 48 | D38: A | E38: =VLOOKUP(C38,'Master List'!A:G,5,FALSE) -> 100 | F38: =VLOOKUP(C38,'2022-002-bottles_csv'!E:L,8,FALSE) -> 0.17 | G38: 304 | H38: 10 | I38: 1 | J38: 16881.2 | K38: 10026.86 | L38: 296.26 | M38: 308.87 | N38: =J38-L38 -> 16584.94 | O38: =K38-M38 -> 9717.99 | P38: =0.0007677*(1.859/(1.859-1))*(N38-O38)*(H38/G38)*I38 -> 0.37529093 | Q38: =0.0007677*(1.859/(1.859-1))*((1.859*O38)-N38)*(H38/G38)*I38 -> 0.080928518 | R38: =N38/O38 -> 1.7066225 | S38: Analysis comment: Filter was essentially disintegrated after shaking to homogenize before reading! | T38: 152
A39: 44757 | B39: =VLOOKUP(C39,'Master List'!A:C,3,FALSE) -> 48-135 | C39: 48 | D39: B | E39: =VLOOKUP(C39,'Master List'!A:G,5,FALSE) -> 100 | F39: =VLOOKUP(C39,'2022-002-bottles_csv'!E:L,8,FALSE) -> 0.17 | G39: 304 | H39: 10 | I39: 1 | J39: 13794.43 | K39: 9701.01 | L39: 305.46 | M39: 318.69 | N39: =J39-L39 -> 13488.97 | O39: =K39-M39 -> 9382.32 | P39: =0.0007677*(1.859/(1.859-1))*(N39-O39)*(H39/G39)*I39 -> 0.22443567 | Q39: =0.0007677*(1.859/(1.859-1))*((1.859*O39)-N39)*(H39/G39)*I39 -> 0.21602546 | R39: =N39/O39 -> 1.4377009 | T39: 312
A40: 44750 | B40: =VLOOKUP(C40,'Master List'!A:C,3,FALSE) -> 48-135 | C40: 49 | D40: A | E40: =VLOOKUP(C40,'Master List'!A:G,5,FALSE) -> 75 | F40: =VLOOKUP(C40,'2022-002-bottles_csv'!E:L,8,FALSE) -> 0.21 | G40: 304 | H40: 10 | I40: 1 | J40: 20035.18 | K40: 12819.74 | L40: 252.94 | M40: 262.98 | N40: =J40-L40 -> 19782.24 | O40: =K40-M40 -> 12556.76 | P40: =0.0007677*(1.859/(1.859-1))*(N40-O40)*(H40/G40)*I40 -> 0.39488523 | Q40: =0.0007677*(1.859/(1.859-1))*((1.859*O40)-N40)*(H40/G40)*I40 -> 0.19460273 | R40: =N40/O40 -> 1.5754255 | T40: 122
A41: 44761 | B41: =VLOOKUP(C41,'Master List'!A:C,3,FALSE) -> 48-135 | C41: 49 | D41: B | E41: =VLOOKUP(C41,'Master List'!A:G,5,FALSE) -> 75 | F41: =VLOOKUP(C41,'2022-002-bottles_csv'!E:L,8,FALSE) -> 0.21 | G41: 304 | H41: 10 | I41: 1 | J41: 19082.32 | K41: 12177.53 | L41: 334.87 | M41: 333.82 | N41: =J41-L41 -> 18747.45 | O41: =K41-M41 -> 11843.71 | P41: =0.0007677*(1.859/(1.859-1))*(N41-O41)*(H41/G41)*I41 -> 0.37730157 | Q41: =0.0007677*(1.859/(1.859-1))*((1.859*O41)-N41)*(H41/G41)*I41 -> 0.17871164 | R41: =N41/O41 -> 1.5829035 | T41: 404
A42: 44754 | B42: =VLOOKUP(C42,'Master List'!A:C,3,FALSE) -> 48-135 | C42: 52 | D42: A | E42: =VLOOKUP(C42,'Master List'!A:G,5,FALSE) -> 50 | F42: =VLOOKUP(C42,'2022-002-bottles_csv'!E:L,8,FALSE) -> 0.22 | G42: 304 | H42: 10 | I42: 1 | J42: 17960.83 | K42: 11278.92 | L42: 296.26 | M42: 308.87 | N42: =J42-L42 -> 17664.57 | O42: =K42-M42 -> 10970.05 | P42: =0.0007677*(1.859/(1.859-1))*(N42-O42)*(H42/G42)*I42 -> 0.36586733 | Q42: =0.0007677*(1.859/(1.859-1))*((1.859*O42)-N42)*(H42/G42)*I42 -> 0.14913116 | R42: =N42/O42 -> 1.6102543 | T42: 158
A43: 44755 | B43: =VLOOKUP(C43,'Master List'!A:C,3,FALSE) -> 48-135 | C43: 52 | D43: B | E43: =VLOOKUP(C43,'Master List'!A:G,5,FALSE) -> 50 | F43: =VLOOKUP(C43,'2022-002-bottles_csv'!E:L,8,FALSE) -> 0.22 | G43: 304 | H43: 10 | I43: 1 | J43: 18923.91 | K43: 11988.73 | L43: 332.42 | M43: 348.04 | N43: =J43-L43 -> 18591.49 | O43: =K43-M43 -> 11640.69 | P43: =0.0007677*(1.859/(1.859-1))*(N43-O43)*(H43/G43)*I43 -> 0.37987348 | Q43: =0.0007677*(1.859/(1.859-1))*((1.859*O43)-N43)*(H43/G43)*I43 -> 0.16660878 | R43: =N43/O43 -> 1.5971124 | T43: 233
A44: 44754 | B44: =VLOOKUP(C44,'Master List'!A:C,3,FALSE) -> 48-135 | C44: 54 | D44: A | E44: =VLOOKUP(C44,'Master List'!A:G,5,FALSE) -> 25 | F44: =VLOOKUP(C44,'2022-002-bottles_csv'!E:L,8,FALSE) -> 0.23 | G44: 304 | H44: 10 | I44: 1 | J44: 19355.87 | K44: 12677.47 | L44: 296.26 | M44: 308.87 | N44: =J44-L44 -> 19059.61 | O44: =K44-M44 -> 12368.6 | P44: =0.0007677*(1.859/(1.859-1))*(N44-O44)*(H44/G44)*I44 -> 0.3656755 | Q44: =0.0007677*(1.859/(1.859-1))*((1.859*O44)-N44)*(H44/G44)*I44 -> 0.21497913 | R44: =N44/O44 -> 1.5409674 | T44: 155
...

Sheet Flags
A1: Quality Flags for Water Samples
A2: Flag | B2: Value Definition
A3: 1 | B3: Sample for this measurement was drawn from water bottle but not analyzed (e.g. broken sample
B4: bottle; nitrate not analyzed in anoxic water; sample lost).
A5: 2 | B5: Acceptable measurement
A6: 3 | B6: Questionable measurement (potential problem observed in sampling, analysis, or value; e.g.
B7: poor agreement between reps but unclear which is better; Niskin integrity questionable but not
B8: severe). Suspected misfire or mis-sample would be noted as an outlier and would be flagged “3”.
A9: 4 | B9: Bad measurement (known problem with sampling or analysis but not serious enough to
B10: completely discard the value; e.g. Niskin integrity was badly compromised; bubble in oxygen
B11: sample; chlorophyll filter askew on funnel).
A12: 5 | B12: Measurement not reported because the value was clearly bad. Use only when a value is clearly
B13: unreasonable or unavailable.
A14: 6 | B14: Mean of replicate measurements (summary of replicates and table of replicate data must be included
B15: in the quality flagged file).
A16: 7 | B16: Manual chromatographic peak measurement.
A17: 8 | B17: Irregular digital chromatographic peak integration.
A18: 9 | B18: Sample not drawn for this measurement from this bottle (planning to sample this bottle, but it didn’t
B19: get collected because the Niskin did not close; there was no water left in the Niskin; the Niskin was
B20: emptied before it was sampled; or we simply forgot).
A22: Chlorophyll IOS Quality Flags
A23: Flag | B23: Value Definition
A24: 1 | B24: Sample was collected but forgotten or lost ex. not filtered, tube/vial broke
A25: 2 | B25: Good value but different than expected such as a lost replicate
A26: 3 | B26: Questionable Measurement
B27: variability of reps > 10%
B28: Chlorophyll sample sat in the fridge >12 hours prior to filtration
B29: filter was stuck to side of vial and only half submerged in acetone after extraction; suspected
B30: misfire/mis-sample as sample doesn’t fit profile
A31: 4 | B31: Known problem with analysis, Bad measurement
B32: Variability of reps > 30%
B33: Known problem with analysis; chl filter was askew; filtration volume uncertain due to large spill
B34: chl sample took >1 hour to filter; known dilution problem
A35: 5 | B35: Measurement not reported, clearly bad, -99.0 Pad value
B36: Forgot to acidify chl sample; sample holder turned so that no light getting into fluorometer;
B37: value clearly unreasonable
A38: 6 | B38: Mean of replicate measurements. Summary of replicates included in the quality flagged file
A39: 9 | B39: Planning to sample but for some reason sample not drawn for this measurement
B40: from this bottle: niskin did not close, no water left in niskin, niskin emptied before sampling

Sheet Master List
A1: Sample Master List for Cruise 2022_02
A3: Sample # | B3: Sample Type | C3: Station | D3: Cruise | E3: Depth | F3: Bottle # | G3: Event # | H3: Ship | I3: Comments
A4: 1 | B4: NUT-F | C4: 50-135 | D4: 2022_02 | E4: 300 | F4: bot 1 | G4: 8
A5: 2 | B5: NUT-F | C5: 50-135 | D5: 2022_02 | E5: 200 | F5: bot 2 | G5: 8 | I5: Duplicate Samples
A6: 4 | B6: NUT-F | C6: 50-135 | D6: 2022_02 | E6: 150 | F6: bot 4 | G6: 8
A7: 5 | B7: NUT-F | C7: 50-135 | D7: 2022_02 | E7: 125 | F7: bot 5 | G7: 8
A8: 6 | B8: NUT-F | C8: 50-135 | D8: 2022_02 | E8: 100 | F8: bot 6 | G8: 8
A9: 9 | B9: NUT-F | C9: 50-135 | D9: 2022_02 | E9: 75 | F9: bot 9 | G9: 8
A10: 12 | B10: NUT-F | C10: 50-135 | D10: 2022_02 | E10: 50 | F10: bot 12 | G10: 8
A11: 14 | B11: NUT-F | C11: 50-135 | D11: 2022_02 | E11: 25 | F11: bot 14 | G11: 8
A12: 20 | B12: NUT-F | C12: 50-135 | D12: 2022_02 | E12: 5 | F12: bot 20 | G12: 8
A13: 4 | B13: CHL | C13: 50-135 | D13: 2022_02 | E13: 150 | F13: bot 4 | G13: 8 | I13: Duplicate Samples
A14: 6 | B14: CHL | C14: 50-135 | D14: 2022_02 | E14: 100 | F14: bot 6 | G14: 8 | I14: Duplicate Samples
A15: 9 | B15: CHL | C15: 50-135 | D15: 2022_02 | E15: 75 | F15: bot 9 | G15: 8 | I15: Duplicate Samples
A16: 12 | B16: CHL | C16: 50-135 | D16: 2022_02 | E16: 50 | F16: bot 12 | G16: 8 | I16: Duplicate Samples
A17: 14 | B17: CHL | C17: 50-135 | D17: 2022_02 | E17: 25 | F17: bot 14 | G17: 8 | I17: Duplicate Samples
A18: 20 | B18: CHL | C18: 50-135 | D18: 2022_02 | E18: 5 | F18: bot 20 | G18: 8 | I18: Duplicate Samples
A19: 12 | B19: HPLC | C19: 50-135 | D19: 2022_02 | E19: 50 | F19: bot 12 | G19: 8 | I19: Duplicate Samples
A20: 14 | B20: HPLC | C20: 50-135 | D20: 2022_02 | E20: 25 | F20: bot 14 | G20: 8 | I20: Duplicate Samples
A21: 20 | B21: HPLC | C21: 50-135 | D21: 2022_02 | E21: 5 | F21: bot 20 | G21: 8 | I21: Duplicate Samples
A22: 17 | B22: HPLC-2 | C22: 50-135 | D22: 2022_02 | E22: 5 | F22: bot 17 | G22: 8 | I22: Duplicate Samples
A23: 20 | B23: FCM | C23: 50-135 | D23: 2022_02 | E23: 5 | F23: bot 20 | G23: 8 | I23: Duplicate Samples
A24: 19 | B24: POM-C&N | C24: 50-135 | D24: 2022_02 | E24: 5 | F24: bot 19 | G24: 8 | I24: Duplicate Samples
A25: 18 | B25: POM-FA | C25: 50-135 | D25: 2022_02 | E25: 5 | F25: bot 18 | G25: 8
A26: 3 | B26: LIGAND | C26: 50-135 | D26: 2022_02 | E26: 150 | F26: bot 3 | G26: 8 | I26: Duplicate Samples
A27: 7 | B27: LIGAND | C27: 50-135 | D27: 2022_02 | E27: 100 | F27: bot 7 | G27: 8 | I27: Duplicate Samples
A28: 11 | B28: LIGAND | C28: 50-135 | D28: 2022_02 | E28: 50 | F28: bot 11 | G28: 8 | I28: Duplicate Samples
A29: 15 | B29: LIGAND | C29: 50-135 | D29: 2022_02 | E29: 25 | F29: bot 15 | G29: 8 | I29: Duplicate Samples
A30: 19 | B30: LIGAND | C30: 50-135 | D30: 2022_02 | E30: 5 | F30: bot 19 | G30: 8 | I30: Duplicate Samples
A31: 8 | B31: eDNA | C31: 50-135 | D31: 2022_02 | E31: 100 | F31: bot 8 | G31: 8 | I31: Duplicate Samples
A32: 10 | B32: eDNA | C32: 50-135 | D32: 2022_02 | E32: 50 | F32: bot 10 | G32: 8 | I32: Duplicate Samples
A33: 13 | B33: eDNA | C33: 50-135 | D33: 2022_02 | E33: 25 | F33: bot 13 | G33: 8 | I33: Duplicate Samples
A34: 16 | B34: eDNA | C34: 50-135 | D34: 2022_02 | E34: 5 | F34: bot 16 | G34: 8 | I34: Duplicate Samples
A35: 21 | B35: NUT-F | C35: 49-135 | D35: 2022_02 | E35: 300 | F35: bot 1 | G35: 12
A36: 22 | B36: NUT-F | C36: 49-135 | D36: 2022_02 | E36: 200 | F36: bot 2 | G36: 12
A37: 24 | B37: NUT-F | C37: 49-135 | D37: 2022_02 | E37: 150 | F37: bot 4 | G37: 12
A38: 25 | B38: NUT-F | C38: 49-135 | D38: 2022_02 | E38: 125 | F38: bot 5 | G38: 12
A39: 28 | B39: NUT-F | C39: 49-135 | D39: 2022_02 | E39: 100 | F39: bot 8 | G39: 12
A40: 29 | B40: NUT-F | C40: 49-135 | D40: 2022_02 | E40: 75 | F40: bot 9 | G40: 12
A41: 32 | B41: NUT-F | C41: 49-135 | D41: 2022_02 | E41: 50 | F41: bot 12 | G41: 12
...

Sheet 2022-002-bottles_csv
A2: Event # | B2: Station | C2: Niskin # | D2: Firing Order | E2: Sample_Number | F2: Oxygen:Dissolved:SBE | G2: Pressure | H2: Depth:Salt_Water | I2: Temperature:Primary | J2: Conductivity:Primary | K2: Transmissivity:1 | L2: Fluorescence:URU:Seapoint | M2: Salinity:T0:C0 | N2: pH:SBE
A3: 8 | B3: 50-135 | C3: 1 | D3: 1 | E3: 1 | F3: 1.524 | G3: 301 | H3: 297.6 | I3: 4.809 | J3: 3.2469 | K3: 66 | L3: 0.09 | M3: 33.8966 | N3: 7.07
A4: 8 | B4: 50-135 | C4: 2 | D4: 2 | E4: 2 | F4: 2.647 | G4: 201.6 | H4: 199.2 | I4: 5.4338 | J4: 3.2873 | K4: 65.9 | L4: 0.09 | M4: 33.7785 | N4: 7.17
A5: 8 | B5: 50-135 | C5: 3 | D5: 3 | E5: 3 | F5: 3.611 | G5: 152.3 | H5: 150.4 | I5: 5.9318 | J5: 3.3129 | K5: 65.9 | L5: 0.09 | M5: 33.5965 | N5: 7.26
A6: 8 | B6: 50-135 | C6: 4 | D6: 4 | E6: 4 | F6: 3.613 | G6: 152.1 | H6: 150.2 | I6: 5.9297 | J6: 3.313 | K6: 65.9 | L6: 0.09 | M6: 33.5989 | N6: 7.26
A7: 8 | B7: 50-135 | C7: 5 | D7: 5 | E7: 5 | F7: 4.877 | G7: 125.6 | H7: 123.9 | I7: 6.0694 | J7: 3.2831 | K7: 65.9 | L7: 0.09 | M7: 33.1391 | N7: 7.37
A8: 8 | B8: 50-135 | C8: 6 | D8: 6 | E8: 6 | F8: 6.828 | G8: 101.3 | H8: 99.8 | I8: 6.6844 | J8: 3.2619 | K8: 62.9 | L8: 0.18 | M8: 32.3259 | N8: 7.55
A9: 8 | B9: 50-135 | C9: 7 | D9: 7 | E9: 7 | F9: 6.824 | G9: 101.5 | H9: 100 | I9: 6.6846 | J9: 3.2619 | K9: 62.9 | L9: 0.18 | M9: 32.3257 | N9: 7.55
A10: 8 | B10: 50-135 | C10: 8 | D10: 8 | E10: 8 | F10: 6.833 | G10: 101.2 | H10: 99.7 | I10: 6.6848 | J10: 3.2619 | K10: 62.9 | L10: 0.19 | M10: 32.3256 | N10: 7.55
A11: 8 | B11: 50-135 | C11: 9 | D11: 9 | E11: 9 | F11: 6.848 | G11: 76 | H11: 74.7 | I11: 6.6868 | J11: 3.2607 | K11: 62.6 | L11: 0.19 | M11: 32.3228 | N11: 7.55
A12: 8 | B12: 50-135 | C12: 10 | D12: 10 | E12: 10 | F12: 6.862 | G12: 50.8 | H12: 49.8 | I12: 6.6848 | J12: 3.2594 | K12: 62.3 | L12: 0.21 | M12: 32.3223 | N12: 7.56
A13: 8 | B13: 50-135 | C13: 11 | D13: 11 | E13: 11 | F13: 6.863 | G13: 50.4 | H13: 49.4 | I13: 6.6849 | J13: 3.2594 | K13: 62.4 | L13: 0.21 | M13: 32.3223 | N13: 7.56
A14: 8 | B14: 50-135 | C14: 12 | D14: 12 | E14: 12 | F14: 6.862 | G14: 50.7 | H14: 49.6 | I14: 6.685 | J14: 3.2594 | K14: 62.4 | L14: 0.21 | M14: 32.3222 | N14: 7.56
... A731: 147 | B731: 51-132 | C731: 21 | D731: 21 | E731: 729 | F731: 6.808 | G731: 6.6 | H731: 5.9 | I731: 7.0859 | J731: 3.2861 | K731: 58 | L731: 0.14 | M731: 32.2583 | N731: 7.75
